Workbook
Name FeaturePhases: 'Lists'!$A$2:$A$2
Name DefectPhases: 'Lists'!$B$2:$B$5
Name LifecycleStatuses: 'Lists'!$C$2:$C$8
Name Severities: 'Lists'!$D$2:$D$5
Name Owners: 'Lists'!$E$2:$E$8
Name TestResults: 'Lists'!$G$2:$G$6
Name ActivationStates: 'Lists'!$I$2:$I$3
Name VerificationStatuses: 'Lists'!$F$2:$F$6
Name FixStatuses: 'Lists'!$J$2:$J$6

Sheet Summary
A1: Portfolio Feature Ledger
A2: Canonical 77-story post-fix reconciliation — 2026-08-23 14:31 America/New_York
A4: Key counts
A5: Features | C5: Candidate defects | E5: Runtime test runs
A6: =COUNTA(Features!$A$2:$A$78) | C6: =COUNTIF(Defects!$C$2:$C$14,"Candidate") | E6: =COUNTA('Test Runs'!$A$2:$A$31)
A8: Counts by phase
A9: Phase | B9: Features | C9: Defects | D9: Test Runs | E9: Total Records
A10: Code Inventory | B10: =COUNTIF(Features!$B$2:$B$78,A10) | C10: =COUNTIF(Defects!$B$2:$B$14,A10) | D10: =COUNTIF('Test Runs'!$B$2:$B$31,A10) | E10: =SUM(B10:D10)
A11: Static UX Audit | B11: =COUNTIF(Features!$B$2:$B$78,A11) | C11: =COUNTIF(Defects!$B$2:$B$14,A11) | D11: =COUNTIF('Test Runs'!$B$2:$B$31,A11) | E11: =SUM(B11:D11)
A12: Runtime Discovery | B12: =COUNTIF(Features!$B$2:$B$78,A12) | C12: =COUNTIF(Defects!$B$2:$B$14,A12) | D12: =COUNTIF('Test Runs'!$B$2:$B$31,A12) | E12: =SUM(B12:D12)
A13: Baseline Verification | B13: =COUNTIF(Features!$B$2:$B$78,A13) | C13: =COUNTIF(Defects!$B$2:$B$14,A13) | D13: =COUNTIF('Test Runs'!$B$2:$B$31,A13) | E13: =SUM(B13:D13)
A14: Post-Fix Verification | B14: =COUNTIF(Features!$B$2:$B$78,A14) | C14: =COUNTIF(Defects!$B$2:$B$14,A14) | D14: =COUNTIF('Test Runs'!$B$2:$B$31,A14) | E14: =SUM(B14:D14)
A15: Baseline status | C15: Fix status | E15: Post-fix status
A16: Status | B16: Count | C16: Status | D16: Count | E16: Status | F16: Count
A17: Not Run | B17: =COUNTIF(Features!$M$2:$M$78,A17) | C17: Not Started | D17: =COUNTIF(Features!$P$2:$P$78,C17) | E17: Not Run | F17: =COUNTIF(Features!$Q$2:$Q$78,E17)
A18: Pass | B18: =COUNTIF(Features!$M$2:$M$78,A18) | C18: In Progress | D18: =COUNTIF(Features!$P$2:$P$78,C18) | E18: Pass | F18: =COUNTIF(Features!$Q$2:$Q$78,E18)
A19: Pass with caveat | B19: =COUNTIF(Features!$M$2:$M$78,A19) | C19: Fixed | D19: =COUNTIF(Features!$P$2:$P$78,C19) | E19: Pass with caveat | F19: =COUNTIF(Features!$Q$2:$Q$78,E19)
A20: Fail | B20: =COUNTIF(Features!$M$2:$M$78,A20) | C20: Deferred | D20: =COUNTIF(Features!$P$2:$P$78,C20) | E20: Fail | F20: =COUNTIF(Features!$Q$2:$Q$78,E20)
A21: Blocked | B21: =COUNTIF(Features!$M$2:$M$78,A21) | C21: Won't Fix | D21: =COUNTIF(Features!$P$2:$P$78,C21) | E21: Blocked | F21: =COUNTIF(Features!$Q$2:$Q$78,E21)
A24: Defect status | C24: Defects by severity | E24: Runtime results
A25: Status | B25: Count | C25: Severity | D25: Count | E25: Status | F25: Count
A26: Documented | B26: =COUNTIF(Defects!$C$2:$C$14,A26) | C26: Critical | D26: =COUNTIF(Defects!$D$2:$D$14,C26) | E26: Passed | F26: =COUNTIF('Test Runs'!$H$2:$H$31,E26)
A27: Candidate | B27: =COUNTIF(Defects!$C$2:$C$14,A27) | C27: High | D27: =COUNTIF(Defects!$D$2:$D$14,C27) | E27: Passed with caveat | F27: =COUNTIF('Test Runs'!$H$2:$H$31,E27)
A28: Planned | B28: =COUNTIF(Defects!$C$2:$C$14,A28) | C28: Medium | D28: =COUNTIF(Defects!$D$2:$D$14,C28) | E28: Candidate | F28: =COUNTIF('Test Runs'!$H$2:$H$31,E28)
A29: In Progress | B29: =COUNTIF(Defects!$C$2:$C$14,A29) | C29: Low | D29: =COUNTIF(Defects!$D$2:$D$14,C29) | E29: Failed | F29: =COUNTIF('Test Runs'!$H$2:$H$31,E29)
A30: Verified | B30: =COUNTIF(Defects!$C$2:$C$14,A30) | E30: Not Run | F30: =COUNTIF('Test Runs'!$H$2:$H$31,E30)
A31: Deferred | B31: =COUNTIF(Defects!$C$2:$C$14,A31)
A32: Closed | B32: =COUNTIF(Defects!$C$2:$C$14,A32)
A34: Instructions and operating rules
A35: 1. All 77 stories retain canonical baseline status/evidence and now have a final Post-Fix Status of Pass or Blocked; Post-Fix Fail and Not Run are zero.
A36: 2. Post-Fix Evidence preserves the raw lane observation and artifact paths. PF-PROJ-011 alone is reconciled from raw Fail to Pass after an intentional PERF-IMG-001 contract update.
A37: 3. Nine authorized product, UX, accessibility, QA, and performance repairs are Fixed/Verified; PERF-IMG-001 was promoted from Candidate before repair verification.
A38: 4. PF-SHELL-004, PF-NAV-008, and PF-PROJ-010 remain honestly Blocked because their preference, unsafe-input, or zero-result preconditions are unavailable in the shipped runtime.
A39: 5. PERF-NAV-001, DESIGN-AI-001, CAND-RUNTIME-METADATA-001, and CAND-RUNTIME-ANALYTICS-001 are Closed/Rejected with retained rationale and evidence.
A40: 6. Stable Feature, Defect, and Test Run IDs are unique; defect links are bidirectionally reconciled; formulas and evidence paths are validated before handoff.
A41: 7. PF-PROJ-015, the catalog story for a client project that left the portfolio, was removed on 2026-10-13; the remaining Feature IDs are unchanged.

Sheet Features
A1: Feature ID | B1: Phase | C1: Area / Route | D1: Actor | E1: User Story | F1: Preconditions | G1: Action | H1: Expected Behavior | I1: Responsive / Accessibility Expectation | J1: Source Evidence | K1: Existing Automated Test Evidence | L1: Activation State | M1: Baseline Status | N1: Baseline Evidence | O1: Defect IDs | P1: Fix Status | Q1: Post-Fix Status | R1: Post-Fix Evidence | S1: Notes | T1: Owner | U1: Created At | V1: Updated At
A2: PF-SHELL-001 | B2: Code Inventory | C2: Global shell / all routes | D2: Visitor | E2: As a visitor, I want an English, dark-themed portfolio shell. | F2: Any route renders. | G2: Load a page. | H2: Root HTML declares English, smooth scrolling, responsive fonts, and an ambient background behind route content. | I2: Device-width viewport; viewport-fit=cover; semantic lang=en; background is aria-hidden. | J2: src/app/layout.tsx:6-20; src/lib/site-metadata.ts:52-56; src/components/AnimatedBackground.tsx:1-13 | K2: src/components/__tests__/AnimatedBackground.test.tsx:5-24; src/app/(site)/layout.test.tsx:98-164 | L2: Active | M2: Pass | N2: Pass — lang=en; dark color-scheme; viewport-fit=cover; fixed ambient environment is aria-hidden; scoped routes render at all required widths. Evidence: /tmp/portfolio-feature-audit/baseline/core/shell-home-head-and-link-safety.json; /tmp/portfolio-feature-audit/baseline/core/home-390-full.png; /tmp/portfolio-feature-audit/baseline/core/about-768-full.png; /tmp/portfolio-feature-audit/baseline/core/not-found-1440-full.png | O2: DESIGN-AI-001 | P2: Won't Fix | Q2: Pass | R2: Pass — At all three required widths, HTML was lang=en with dark color scheme, 320px minimum, smooth scrolling in normal mode, and an ambient background behind visible content. Evidence: /tmp/portfolio-feature-audit/postfix/core/390/home-diagnostics.json; /tmp/portfolio-feature-audit/postfix/core/390/home-full.png; /tmp/portfolio-feature-audit/postfix/core/1440/home-full.png | T2: Unassigned | U2: 46257 | V2: 46257.605
A3: PF-SHELL-002 | B3: Code Inventory | C3: Global styles | D3: Keyboard/low-vision visitor | E3: As a keyboard user, I want visible focus and no horizontal page overflow. | F3: Focusable control exists. | G3: Tab through controls or render at narrow width. | H3: .focus-ring shows a 2px cyan outline with offset; document clips horizontal overflow and has a 320px minimum. | I3: Focus-visible only; avoids accidental horizontal scrolling. | J3: src/app/globals.css:47-59,77-85 | K3: src/app/globals.test.ts:9-56; e2e/helpers.ts:3-10 | L3: Active | M3: Pass | N3: Pass — Tab walk covered every Home control at desktop/mobile; settled focus ring is 2px #a9edfa with 3px offset; document scrollWidth equals clientWidth on Home, About, and 404 at 390/768/1440. Evidence: /tmp/portfolio-feature-audit/baseline/core/home-1440-focus-walk.jsonl; /tmp/portfolio-feature-audit/baseline/core/home-full-list-focus-after-transition.json; /tmp/portfolio-feature-audit/baseline/core/home-390-dom.json; /tmp/portfolio-feature-audit/baseline/core/about-390-dom.json; /tmp/portfolio-feature-audit/baseline/core/not-found-390-dom.json | P3: Not Started | Q3: Pass | R3: Pass — First Tab revealed a solid 2px rgb(169,237,250) outline with 3px offset; document width equaled viewport at 390, exact 768, and 1440. Evidence: /tmp/portfolio-feature-audit/postfix/core/390/skip-focus.json; /tmp/portfolio-feature-audit/postfix/core/390/home-diagnostics.json; /tmp/portfolio-feature-audit/postfix/core/768/home-diagnostics.json; /tmp/portfolio-feature-audit/postfix/core/1440/home-diagnostics.json | T3: Unassigned | U3: 46257 | V3: 46257.605
A4: PF-SHELL-003 | B4: Code Inventory | C4: Global motion | D4: Motion-sensitive visitor | E4: As a motion-sensitive visitor, I want animation removed. | F4: OS/browser requests reduced motion. | G4: Load or interact. | H4: Smooth scroll, entrance animations, orbs, hover/active transforms, and transitions are disabled while content stays visible. | I4: Honors prefers-reduced-motion: reduce. | J4: src/app/globals.css:310-357 | K4: src/app/globals.test.ts:19-34 | L4: Active | M4: Pass | N4: Pass — prefers-reduced-motion matched; html scroll behavior became auto; sampled orbs, reveal elements, links, and transitions reported animation none/0s and content opacity 1. Evidence: /tmp/portfolio-feature-audit/baseline/core/about-1440-reduced-motion.json; /tmp/portfolio-feature-audit/baseline/core/about-1440-reduced-motion.png | P4: Not Started | Q4: Pass | R4: Pass — With reduced motion emulated, scroll became auto, reveal/orb animation became none/0s, transform became none, transition duration became 0s, and h1 content remained visible. Evidence: /tmp/portfolio-feature-audit/postfix/core/390/reduced-motion.json | T4: Unassigned | U4: 46257 | V4: 46257.605
A5: PF-SHELL-004 | B5: Code Inventory | C5: Global transparency | D5: Transparency-sensitive visitor | E5: As a visitor requesting reduced transparency, I want opaque surfaces. | F5: OS/browser requests reduced transparency. | G5: Load a page. | H5: Glass/window/glow surfaces become opaque, backdrop blur is removed, and noise overlay is hidden. | I5: Honors prefers-reduced-transparency: reduce; fallback also exists for browsers without backdrop-filter. | J5: src/app/globals.css:359-380 | K5: src/app/globals.test.ts:35-47 | L5: Active | M5: Blocked | N5: Blocked — The required agent-browser Chromium session only exposes color-scheme and reduced-motion media emulation; it cannot emulate prefers-reduced-transparency, so the runtime preference branch could not be activated without out-of-scope instrumentation. Evidence: /tmp/portfolio-feature-audit/baseline/core/reduced-transparency-emulation-limit.txt | P5: Deferred | Q5: Blocked | R5: Blocked — The configured agent-browser Chromium session cannot emulate prefers-reduced-transparency. Static CSS/unit coverage passed, but the runtime media state could not be activated honestly. Evidence: /tmp/portfolio-feature-audit/postfix/core/static-unit-verification.txt; /tmp/portfolio-feature-audit/postfix/core/feature-contracts.json | T5: Unassigned | U5: 46257 | V5: 46257.605
A6: PF-SHELL-005 | B6: Code Inventory | C6: Global responsive clearance | D6: Mobile/tablet visitor | E6: As a visitor, I want content and anchor targets clear of fixed navigation. | F6: Viewport is below or above 48rem. | G6: Navigate/scroll to content. | H6: Mobile bottom clearance includes safe area; at 48rem+ top scroll padding becomes 9rem and bottom padding resets to 2rem. | I6: Uses safe-area env vars; exact 768px handoff. | J6: src/app/globals.css:26,47-51,303-308; src/app/(site)/layout.tsx:21-28 | K6: src/app/globals.test.ts:48-56; src/app/(site)/layout.test.tsx:166-174; e2e/navigation.spec.ts:8-22 | L6: Active | M6: Pass | N6: Pass — At 390 the dock is fixed 92px high and main padding-bottom is 192px; at exact 768 only the 92px header is visible, scroll-padding-top is 144px, main padding-bottom is 48px, and no overflow occurs. Evidence: /tmp/portfolio-feature-audit/baseline/core/home-390-dom.json; /tmp/portfolio-feature-audit/baseline/core/home-768-dom.json; /tmp/portfolio-feature-audit/baseline/core/not-found-390-full.png; /tmp/portfolio-feature-audit/baseline/core/not-found-768-full.png | O6: RESP-CONTACT-001 | P6: Fixed | Q6: Pass | R6: Pass — Mobile main padding-bottom was 192px below the 92px fixed dock. At exact 768, top/scroll padding was 144px, bottom main padding 48px, scroll bottom padding 32px, and headings cleared the dock. Evidence: /tmp/portfolio-feature-audit/postfix/core/390/home-diagnostics.json; /tmp/portfolio-feature-audit/postfix/core/768/home-diagnostics.json; /tmp/portfolio-feature-audit/postfix/core/768/home-full.png | T6: Unassigned | U6: 46257 | V6: 46257.605
A7: PF-NAV-001 | B7: Code Inventory | C7: All main routes | D7: Keyboard visitor | E7: As a keyboard user, I want to bypass repeated navigation. | F7: Home/site/404 shell rendered. | G7: Focus and activate “Skip to content.” | H7: Focus-revealed link moves to focusable #main-content. | I7: Visually hidden until focus; safe-area-aware placement; main has tabIndex=-1. | J7: src/components/HomeShell.tsx:3-16; src/app/(site)/layout.tsx:13-28; src/app/not-found.tsx:35-49 | K7: src/app/not-found.test.tsx:27-46; no direct activation E2E | L7: Active | M7: Pass | N7: Pass — On Home and 404 at 390, first Tab exposed a full-width 44px target with 2px cyan outline; Enter set #main-content and focused main with tabIndex -1. About exposes the same link in its accessibility tree. Evidence: /tmp/portfolio-feature-audit/baseline/core/home-390-skip-focused.json; /tmp/portfolio-feature-audit/baseline/core/home-390-skip-activated.json; /tmp/portfolio-feature-audit/baseline/core/not-found-390-skip-focused.json; /tmp/portfolio-feature-audit/baseline/core/not-found-390-skip-activated.json; /tmp/portfolio-feature-audit/baseline/core/about-1440-a11y.txt | P7: Not Started | Q7: Pass | R7: Pass — First Tab visibly focused Skip to content; Enter changed the hash and focused MAIN#main-content. Evidence: /tmp/portfolio-feature-audit/postfix/core/390/skip-focus.json; /tmp/portfolio-feature-audit/postfix/core/390/skip-activated.json | T7: Unassigned | U7: 46257 | V7: 46257.605
A8: PF-NAV-002 | B8: Code Inventory | C8: Primary navigation / all public routes | D8: Desktop/tablet visitor | E8: As a visitor, I want access to Home, About, Projects, and Contact. | F8: Viewport >=48rem. | G8: Activate a header nav item. | H8: Navigate to /, /about, /projects, or /contact; Home forces document navigation, others avoid prefetch. | I8: Header is hidden below 48rem; 44px minimum controls; aria-label="Primary navigation". | J8: src/data/navigation.ts:14-19; src/components/Sidebar.tsx:12-76; src/components/NavLink.tsx:39-62 | K8: src/components/__tests__/Sidebar.test.tsx:11-96; src/components/__tests__/NavLink.test.tsx:23-93; e2e/navigation.spec.ts:8-22 | L8: Active | M8: Pass | N8: Pass — All four destinations navigated at exact 768/1440. An injected marker persisted across About/Projects/Contact SPA transitions and cleared on Home, proving Home document navigation. Visible route controls are 44px minimum. Existing PERF-NAV-001 is separately confirmed for failure/latency feedback. Evidence: /tmp/portfolio-feature-audit/baseline/core/nav-desktop-about-projects.json; /tmp/portfolio-feature-audit/baseline/core/nav-desktop-projects-contact.json; /tmp/portfolio-feature-audit/baseline/core/nav-desktop-contact-about.json; /tmp/portfolio-feature-audit/baseline/core/nav-desktop-about-home.json; /tmp/portfolio-feature-audit/baseline/core/home-768-dom.json | O8: PERF-NAV-001 | P8: Won't Fix | Q8: Pass | R8: Pass — All four destinations were present in the only visible primary navigation; actual dock/header and CTA activation reached Home, About, Projects, and Contact. Evidence: /tmp/portfolio-feature-audit/postfix/core/390/home-diagnostics.json; /tmp/portfolio-feature-audit/postfix/core/390/mobile-dock-about-url.txt; /tmp/portfolio-feature-audit/postfix/core/390/mobile-dock-home-url.txt; /tmp/portfolio-feature-audit/postfix/core/390/home-explore-url.txt; /tmp/portfolio-feature-audit/postfix/core/390/home-start-project-url.txt; /tmp/portfolio-feature-audit/postfix/core/768/nav-about-url.txt | T8: Unassigned | U8: 46257 | V8: 46257.605
A9: PF-NAV-003 | B9: Code Inventory | C9: Primary navigation / all public routes | D9: Mobile visitor | E9: As a mobile visitor, I want a reachable bottom dock. | F9: Viewport <48rem. | G9: Tap one of four route items. | H9: Navigate to the selected route through a fixed bottom dock. | I9: Safe-area paddings; minimum 56px items; truncated labels; exactly one primary nav visible. | J9: src/components/MobileNav.tsx:6-46; src/components/HomeNavigation.tsx:65-73 | K9: src/components/__tests__/MobileNav.test.tsx:10-53; e2e/navigation.spec.ts:8-22; e2e/helpers.ts:13-27 | L9: Active | M9: Pass | N9: Pass — At 390 only the mobile dock is visible; it is fixed, 92px high, and all four items are 85x58px. Home/About/Projects/Contact were each reached through the dock with the correct active state. Evidence: /tmp/portfolio-feature-audit/baseline/core/home-390-dom.json; /tmp/portfolio-feature-audit/baseline/core/nav-mobile-about.txt; /tmp/portfolio-feature-audit/baseline/core/nav-mobile-projects.txt; /tmp/portfolio-feature-audit/baseline/core/nav-mobile-contact.txt; /tmp/portfolio-feature-audit/baseline/core/home-390-focus-walk.jsonl | O9: PERF-NAV-001 | P9: Won't Fix | Q9: Pass | R9: Pass — At 390 there was exactly one visible fixed bottom navigation (92px high) with four routes; About and Home activations navigated correctly. Evidence: /tmp/portfolio-feature-audit/postfix/core/390/home-diagnostics.json; /tmp/portfolio-feature-audit/postfix/core/390/mobile-dock-about-url.txt; /tmp/portfolio-feature-audit/postfix/core/390/mobile-dock-home-url.txt | T9: Unassigned | U9: 46257 | V9: 46257.605
A10: PF-NAV-004 | B10: Code Inventory | C10: Primary navigation state | D10: Visitor/assistive tech | E10: As a visitor, I want the current route identified. | F10: Current pathname equals a nav href. | G10: Load/switch route. | H10: Active solid icon/style is used and internal link exposes aria-current="page"; 404 marks none active. | I10: Screen-reader current-page semantics; icon decorative. | J10: src/components/NavLink.tsx:27-34,53-61; src/components/Sidebar.tsx:43-75; src/components/MobileNav.tsx:13-42; src/app/not-found.tsx:42-44 | K10: src/components/__tests__/NavLink.test.tsx:47-79; src/components/__tests__/MobileNav.test.tsx:37-53; src/components/__tests__/Sidebar.test.tsx:49-61 | L10: Active | M10: Pass | N10: Pass — Home, About, Projects, and Contact each exposed one visible current route after navigation; the invalid route exposed none. Evidence: /tmp/portfolio-feature-audit/baseline/core/nav-desktop-about-home.json; /tmp/portfolio-feature-audit/baseline/core/nav-desktop-about-projects.json; /tmp/portfolio-feature-audit/baseline/core/nav-desktop-projects-contact.json; /tmp/portfolio-feature-audit/baseline/core/nav-desktop-contact-about.json; /tmp/portfolio-feature-audit/baseline/core/not-found-390-dom.json | P10: Not Started | Q10: Pass | R10: Pass — Home and About each exposed exactly the correct current route across mobile/tablet/desktop; the invalid route exposed zero current links. Evidence: /tmp/portfolio-feature-audit/postfix/core/390/home-diagnostics.json; /tmp/portfolio-feature-audit/postfix/core/390/about-diagnostics.json; /tmp/portfolio-feature-audit/postfix/core/768/about-diagnostics.json; /tmp/portfolio-feature-audit/postfix/core/390/not-found-diagnostics.json | T10: Unassigned | U10: 46257 | V10: 46257.605
A11: PF-NAV-005 | B11: Code Inventory | C11: Header CTA | D11: Prospective client | E11: As a prospect, I want a persistent way to start a project. | F11: Any public route rendered. | G11: Activate “Start a project.” | H11: Navigate to /contact. | I11: Icon-only presentation at constrained widths retains aria-label; minimum 44px target. | J11: src/components/Sidebar.tsx:106-117; src/components/HomeNavigation.tsx:58-60 | K11: src/components/__tests__/Sidebar.test.tsx:88-96 | L11: Active | M11: Pass | N11: Pass — At exact 768 the CTA is named Start a project, measures 155.8x44px, and navigates to /contact; Home hero CTA keyboard activation also reached /contact. Evidence: /tmp/portfolio-feature-audit/baseline/core/header-cta-768-metrics.json; /tmp/portfolio-feature-audit/baseline/core/header-cta-768-result.txt; /tmp/portfolio-feature-audit/baseline/core/home-hero-start-keyboard-result.txt | O11: PERF-NAV-001 | P11: Won't Fix | Q11: Pass | R11: Pass — The 1440 header CTA was visible with an accessible label and activated /contact; the Home primary CTA also reached /contact. Evidence: /tmp/portfolio-feature-audit/postfix/core/1440/home-diagnostics.json; /tmp/portfolio-feature-audit/postfix/core/1440/header-cta-url.txt; /tmp/portfolio-feature-audit/postfix/core/390/home-start-project-url.txt | T11: Unassigned | U11: 46257 | V11: 46257.605
A12: PF-NAV-006 | B12: Code Inventory | C12: Header social links | D12: Visitor | E12: As a visitor, I want professional profile links. | F12: Viewport >=96rem (2xl) header social nav visible. | G12: Activate GitHub, LinkedIn, or Defendre Solutions icon. | H12: Open configured external destination in a new tab with opener protection. | I12: Dedicated aria-label per icon; icons hidden from AT; 44px targets. | J12: src/data/socials.ts:4-20; src/components/Sidebar.tsx:92-104; src/components/HomeNavigation.tsx:51-57 | K12: src/components/__tests__/Sidebar.test.tsx:62-73; src/components/__tests__/HomeNavigation.test.tsx:5-13; src/data/__tests__/socials.test.ts:3-39 | L12: Active | M12: Pass | N12: Pass — At 1536 all three controls were visible at 44x44px with noopener noreferrer and opened the configured GitHub, LinkedIn, and Defendre Solutions destinations. Existing A11Y-EXT-001 disclosure gap remains. Evidence: /tmp/portfolio-feature-audit/baseline/core/home-1536-interactive.txt; /tmp/portfolio-feature-audit/baseline/core/home-1536-external-links.json; /tmp/portfolio-feature-audit/baseline/core/social-github-tabs.txt; /tmp/portfolio-feature-audit/baseline/core/social-linkedin-tabs.txt; /tmp/portfolio-feature-audit/baseline/core/social-studio-tabs.txt | O12: A11Y-EXT-001 | P12: Fixed | Q12: Pass | R12: Pass — At supplementary 1536, GitHub, LinkedIn, and studio controls were visible with disclosed new-tab names, protected rel values, and correct destinations; all three were activated successfully. Evidence: /tmp/portfolio-feature-audit/postfix/core/1440/social-1536-diagnostics.json; /tmp/portfolio-feature-audit/postfix/core/external/social-github-tabs.txt; /tmp/portfolio-feature-audit/postfix/core/external/social-linkedin-tabs.txt; /tmp/portfolio-feature-audit/postfix/core/external/social-studio-tabs.txt | T12: Unassigned | U12: 46257 | V12: 46257.605
A13: PF-NAV-007 | B13: Code Inventory | C13: Footer / home and site routes | D13: Visitor | E13: As a visitor, I want authorship attribution. | F13: Page shell renders. | G13: Activate Defendre Solutions footer link. | H13: Open https://defendresolutions.com in a protected new tab; display “Built with intent.” | I13: Centered stack on mobile, split row at sm; link has focus treatment. | J13: src/components/HomeShell.tsx:11-14; src/app/(site)/layout.tsx:30-49 | K13: src/app/(site)/layout.test.tsx:152-164; no direct footer-link assertion | L13: Active | M13: Pass | N13: Pass — Home and About footers expose the studio link plus Built with intent; both opened the studio in a protected new tab and participated in the complete keyboard focus walk. Evidence: /tmp/portfolio-feature-audit/baseline/core/home-1440-a11y.txt; /tmp/portfolio-feature-audit/baseline/core/about-1440-a11y.txt; /tmp/portfolio-feature-audit/baseline/core/home-footer-studio-tabs.txt; /tmp/portfolio-feature-audit/baseline/core/about-footer-studio-tabs.txt; /tmp/portfolio-feature-audit/baseline/core/home-1440-focus-walk.jsonl | O13: A11Y-EXT-001 | P13: Fixed | Q13: Pass | R13: Pass — Footer attribution and Built with intent rendered; its disclosed Defendre Solutions link opened the correct protected external destination. Evidence: /tmp/portfolio-feature-audit/postfix/core/1440/home-diagnostics.json; /tmp/portfolio-feature-audit/postfix/core/external/footer-studio-tabs.txt; /tmp/portfolio-feature-audit/postfix/core/1440/about-full.png | T13: Unassigned | U13: 46257 | V13: 46257.605
A14: PF-NAV-008 | B14: Code Inventory | C14: Link safety utility | D14: Visitor/security system | E14: As a visitor, I want unsafe URLs neutralized. | F14: Component receives an href. | G14: Render/click link. | H14: Allow relative/anchor/http/https/mailto/tel; block protocol-relative, javascript/data, empty, or invalid href by substituting # or omitting a link. | I14: Security behavior; external blank targets receive noopener noreferrer. | J14: src/utils/url.ts:1-23; src/components/NavLink.tsx:36-46; src/components/ProjectCard.tsx:67,204-218; src/app/(site)/contact/page.tsx:30-35 | K14: src/utils/__tests__/url.test.ts:4-32; src/components/__tests__/NavLink.test.tsx:39-91; src/components/__tests__/ProjectCard.test.tsx:45-76 | L14: Active | M14: Blocked | N14: Blocked — Runtime DOM crawl found only anchor, relative, and https hrefs, no unsafe rendered anchors, and secure rel on blank-target links. No public control accepts an href, so the negative unsafe-input substitution path cannot be exercised through the requested user-story browser lane without component instrumentation. Evidence: /tmp/portfolio-feature-audit/baseline/core/shell-home-head-and-link-safety.json; /tmp/portfolio-feature-audit/baseline/core/home-1536-external-links.json | P14: Deferred | Q14: Blocked | R14: Blocked — Relative/http/https links worked in the fixed browser build and 15 URL/NavLink/global unit cases passed. The fixed UI exposes no controllable unsafe href input, so negative production-DOM substitution could not be injected without modifying source. Evidence: /tmp/portfolio-feature-audit/postfix/core/static-unit-verification.txt; /tmp/portfolio-feature-audit/postfix/core/390/home-diagnostics.json | T14: Unassigned | U14: 46257 | V14: 46257.605
A15: PF-HOME-001 | B15: Code Inventory | C15: / hero | D15: Visitor | E15: As a visitor, I want Steve’s positioning and availability immediately. | F15: Home route loads. | G15: Read hero. | H15: Show availability, veteran/full-stack founder identity, main value proposition, and build scope. | I15: Fluid heading; content/image order swaps at lg; semantic h1; decorative indicators hidden. | J15: src/app/(home)/page.tsx:31-71 | K15: src/app/(home)/page.test.tsx:51-70 | L15: Active | M15: Pass | N15: Pass — All required positioning copy and one h1 are present; portrait precedes copy on mobile and moves beside copy at desktop; 390/768/1440 captures are legible without overflow. Evidence: /tmp/portfolio-feature-audit/baseline/core/home-1440-a11y.txt; /tmp/portfolio-feature-audit/baseline/core/home-390-full.png; /tmp/portfolio-feature-audit/baseline/core/home-768-full.png; /tmp/portfolio-feature-audit/baseline/core/home-1440-full.png | O15: DESIGN-AI-001 | P15: Won't Fix | Q15: Pass | R15: Pass — Responsive captures/accessibility tree showed the semantic h1, availability badge, veteran/full-stack identity, founder narrative, and application/booking/portfolio/tools scope. Evidence: /tmp/portfolio-feature-audit/postfix/core/390/home-a11y.txt; /tmp/portfolio-feature-audit/postfix/core/390/home-full.png; /tmp/portfolio-feature-audit/postfix/core/1440/home-full.png | T15: Unassigned | U15: 46257 | V15: 46257.605
A16: PF-HOME-002 | B16: Code Inventory | C16: / hero external link | D16: Visitor | E16: As a visitor, I want to learn about Defendre Solutions. | F16: Home hero visible. | G16: Activate “Defendre Solutions.” | H16: Open https://defendresolutions.com in a protected new tab. | I16: Underlined, focus-ring link; readable inline. | J16: src/app/(home)/page.tsx:59-70 | K16: src/app/(home)/page.test.tsx:51-70 | L16: Active | M16: Pass | N16: Pass — The link has target blank plus noopener noreferrer, opened the intended studio, and received a visible 2px focus outline. Existing A11Y-EXT-001 new-tab-name disclosure gap remains. Evidence: /tmp/portfolio-feature-audit/baseline/core/home-1536-external-links.json; /tmp/portfolio-feature-audit/baseline/core/home-hero-studio-tabs.txt; /tmp/portfolio-feature-audit/baseline/core/home-hero-studio-focus-diagnostic.json | O16: A11Y-EXT-001 | P16: Fixed | Q16: Pass | R16: Pass — Accessible name now discloses the new tab; target/rel were protected and activation opened Defendre Solutions. Evidence: /tmp/portfolio-feature-audit/postfix/core/390/home-interactive.txt; /tmp/portfolio-feature-audit/postfix/core/390/home-diagnostics.json; /tmp/portfolio-feature-audit/postfix/core/external/home-studio-tabs.txt | T16: Unassigned | U16: 46257 | V16: 46257.605
A17: PF-HOME-003 | B17: Code Inventory | C17: / hero primary CTA | D17: Prospect | E17: As a prospect, I want to start a project. | F17: Home hero visible. | G17: Activate “Start a project.” | H17: Navigate to /contact. | I17: Stacks full-width on small screens, row at sm; minimum 48px. | J17: src/app/(home)/page.tsx:73-80 | K17: src/app/(home)/page.test.tsx:51-70 | L17: Active | M17: Pass | N17: Pass — Keyboard Enter reached /contact; control measured 48px high at desktop and 316x48px at 390. Evidence: /tmp/portfolio-feature-audit/baseline/core/home-hero-start-keyboard-focus.json; /tmp/portfolio-feature-audit/baseline/core/home-hero-start-keyboard-result.txt; /tmp/portfolio-feature-audit/baseline/core/home-390-dom.json | P17: Not Started | Q17: Pass | R17: Pass — The visible Home primary CTA activation reached /contact at mobile width. Evidence: /tmp/portfolio-feature-audit/postfix/core/390/home-start-project-url.txt; /tmp/portfolio-feature-audit/postfix/core/390/home-full.png | T17: Unassigned | U17: 46257 | V17: 46257.605
A18: PF-HOME-004 | B18: Code Inventory | C18: / hero secondary CTA | D18: Visitor | E18: As a visitor, I want to explore work. | F18: Home hero visible. | G18: Activate “Explore the work.” | H18: Navigate to /projects. | I18: Same responsive CTA group and focus/hover states as primary. | J18: src/app/(home)/page.tsx:81-86 | K18: src/app/(home)/page.test.tsx:51-70 | L18: Active | M18: Pass | N18: Pass — Click reached /projects; mobile capture shows a full-width 48px secondary CTA and the focus walk reports a 2px visible outline. Evidence: /tmp/portfolio-feature-audit/baseline/core/home-explore-result.txt; /tmp/portfolio-feature-audit/baseline/core/home-390-full.png; /tmp/portfolio-feature-audit/baseline/core/home-390-focus-walk.jsonl | P18: Not Started | Q18: Pass | R18: Pass — The visible secondary CTA activation reached /projects at mobile width. Evidence: /tmp/portfolio-feature-audit/postfix/core/390/home-explore-url.txt; /tmp/portfolio-feature-audit/postfix/core/390/home-full.png | T18: Unassigned | U18: 46257 | V18: 46257.605
A19: PF-HOME-005 | B19: Code Inventory | C19: / headshot | D19: Visitor/assistive tech | E19: As a visitor, I want a clear founder portrait and identity. | F19: Image optimizer available. | G19: Load hero image. | H19: Show responsive, high-priority headshot with founder/engineer/veteran caption. | I19: Descriptive alt; responsive sizes; eager high-priority image. | J19: src/app/(home)/page.tsx:90-112; src/components/ResponsiveImage.tsx:20-43 | K19: src/app/(home)/page.test.tsx:51-70; no direct optimizer selection test | L19: Active | M19: Pass | N19: Pass — Accessibility tree exposes the descriptive founder portrait; runtime image is eager/high priority and the caption is visible at 390/768/1440. Existing PERF-IMG-001 concerns hidden/below-fold media, not this required LCP portrait. Evidence: /tmp/portfolio-feature-audit/baseline/core/home-1440-a11y.txt; /tmp/portfolio-feature-audit/baseline/core/home-390-dom.json; /tmp/portfolio-feature-audit/baseline/core/home-390-full.png | O19: PERF-IMG-001 | P19: Fixed | Q19: Pass | R19: Pass — The visible hero portrait retained descriptive founder/veteran/full-stack alt, eager loading, high fetch priority, responsive geometry, and identity caption. The hidden nav avatar was separately lazy/low. Evidence: /tmp/portfolio-feature-audit/postfix/core/390/home-diagnostics.json; /tmp/portfolio-feature-audit/postfix/core/768/home-diagnostics.json; /tmp/portfolio-feature-audit/postfix/core/1440/home-diagnostics.json | T19: Unassigned | U19: 46257 | V19: 46257.605
A20: PF-HOME-006 | B20: Code Inventory | C20: / telemetry | D20: Visitor | E20: As a visitor, I want quick operating context. | F20: Home hero visible. | G20: Read telemetry. | H20: Present Studio, Build mode, and Operating edge as definition data. | I20: One-column mobile, three columns at sm; semantic dl/dt/dd. | J20: src/app/(home)/page.tsx:6-19,115-129 | K20: src/app/(home)/page.test.tsx:51-70 | L20: Active | M20: Pass | N20: Pass — Accessibility snapshot exposes three term/definition pairs; captures show one-column at 390 and three columns at 768/1440. Evidence: /tmp/portfolio-feature-audit/baseline/core/home-1440-a11y.txt; /tmp/portfolio-feature-audit/baseline/core/home-390-full.png; /tmp/portfolio-feature-audit/baseline/core/home-768-full.png | P20: Not Started | Q20: Pass | R20: Pass — All three dt/dd pairs rendered with the expected values and responsive layout. Evidence: /tmp/portfolio-feature-audit/postfix/core/390/home-diagnostics.json; /tmp/portfolio-feature-audit/postfix/core/1440/home-full.png | T20: Unassigned | U20: 46257 | V20: 46257.605
A21: PF-HOME-007 | B21: Code Inventory | C21: / selected work | D21: Visitor | E21: As a visitor, I want a curated subset of work. | F21: Project catalog has >=4 records. | G21: Scroll/read selected work. | H21: Render first four catalog projects; first is featured and remaining are compact. | I21: section labelled by h2; responsive cards. | J21: src/app/(home)/page.tsx:28-30,132-166 | K21: src/app/(home)/page.test.tsx:71-90 | L21: Active | M21: Pass | N21: Pass — Exactly four projects appear under A constellation of shipped systems; desktop metrics/capture show the featured/compact constellation and every card destination opened correctly. Existing PERF-IMG-001 and A11Y-IMG-001 are separately confirmed. Evidence: /tmp/portfolio-feature-audit/baseline/core/home-1440-a11y.txt; /tmp/portfolio-feature-audit/baseline/core/home-1440-full.png; /tmp/portfolio-feature-audit/baseline/core/home-project-studio-tabs.txt; /tmp/portfolio-feature-audit/baseline/core/home-project-freevoice-tabs.txt; /tmp/portfolio-feature-audit/baseline/core/home-project-braids-tabs.txt; /tmp/portfolio-feature-audit/baseline/core/home-project-traces-tabs.txt | O21: PERF-IMG-001; DESIGN-AI-001; A11Y-IMG-001 | P21: Fixed | Q21: Pass | R21: Pass — Exactly Defendre Solutions, FreeVoiceTranscribe, BraidsbyRose, and Traces rendered under the labelled h2. Geometry showed the first featured and remaining compact; every project image was lazy/auto priority. Evidence: /tmp/portfolio-feature-audit/postfix/core/390/home-diagnostics.json; /tmp/portfolio-feature-audit/postfix/core/768/home-diagnostics.json; /tmp/portfolio-feature-audit/postfix/core/1440/home-diagnostics.json | T21: Unassigned | U21: 46257 | V21: 46257.605
A22: PF-HOME-008 | B22: Code Inventory | C22: / selected work layout | D22: Mobile/tablet/desktop visitor | E22: As a visitor, I want project cards usable at any width. | F22: Selected work rendered. | G22: Horizontal swipe on mobile or scan grid at tablet+. | H22: Mobile uses snap-mandatory horizontal rail; md switches to 12-column non-scrolling constellation. | I22: Avoids hidden content; snap-center; responsive span/offset placement. | J22: src/app/(home)/page.tsx:21-26,154-165 | K22: No direct layout assertion; overflow coverage is on /projects, not / | L22: Active | M22: Pass | N22: Pass — At 390 the four-card container is 358px client/1212px scroll, overflow auto, x mandatory, with center snap on all cards; scrolling to max brought the last card wholly into view. Exact 768 has no wide scroll container and renders the constellation grid. Evidence: /tmp/portfolio-feature-audit/baseline/core/home-390-rail-before.json; /tmp/portfolio-feature-audit/baseline/core/home-390-rail-after.json; /tmp/portfolio-feature-audit/baseline/core/home-390-rail-after.png; /tmp/portfolio-feature-audit/baseline/core/home-768-dom.json; /tmp/portfolio-feature-audit/baseline/core/home-768-full.png | P22: Not Started | Q22: Pass | R22: Pass — At 390 the rail used column flow, overflow auto, and x mandatory snapping. At exact 768 it used row flow, 12 columns, visible overflow, and no horizontal document overflow. Evidence: /tmp/portfolio-feature-audit/postfix/core/390/home-diagnostics.json; /tmp/portfolio-feature-audit/postfix/core/768/home-diagnostics.json; /tmp/portfolio-feature-audit/postfix/core/390/home-full.png; /tmp/portfolio-feature-audit/postfix/core/768/home-full.png | T22: Unassigned | U22: 46257 | V22: 46257.605
A23: PF-HOME-009 | B23: Code Inventory | C23: / full-project links | D23: Visitor | E23: As a visitor, I want the full archive after the curated subset. | F23: Home selected work visible. | G23: Activate “View the full project list” (or hero secondary CTA). | H23: Navigate to /projects. | I23: 44px minimum, descriptive text, decorative arrow. | J23: src/app/(home)/page.tsx:145-151 | K23: src/app/(home)/page.test.tsx:71-90 | L23: Active | M23: Pass | N23: Pass — Both controls reached /projects; the full-list link measured 44px high and succeeded with keyboard Enter. Evidence: /tmp/portfolio-feature-audit/baseline/core/home-full-list-keyboard-result.txt; /tmp/portfolio-feature-audit/baseline/core/home-explore-result.txt; /tmp/portfolio-feature-audit/baseline/core/home-1440-focus-walk.jsonl | P23: Not Started | Q23: Pass | R23: Pass — Both Explore the work and View the full project list were activated and reached /projects. Evidence: /tmp/portfolio-feature-audit/postfix/core/390/home-explore-url.txt; /tmp/portfolio-feature-audit/postfix/core/390/home-full-list-url.txt | T23: Unassigned | U23: 46257 | V23: 46257.605
A24: PF-ABOUT-001 | B24: Code Inventory | C24: /about identity narrative | D24: Visitor | E24: As a visitor, I want Steve’s background and approach. | F24: About route loads. | G24: Read page header. | H24: Show veteran/founder/full-stack identity, current mission, and product-to-delivery narrative. | I24: Responsive portrait/columns; descriptive image alt; semantic h1. | J24: src/app/(site)/about/page.tsx:83-135 | K24: src/app/(site)/about/page.test.tsx:5-21 | L24: Active | M24: Pass | N24: Pass — All narrative content and one About Me h1 are present; portrait alt is Steve Defendre, founder of Defendre Solutions; stable 390/768/1440 captures reflow correctly without overflow. Evidence: /tmp/portfolio-feature-audit/baseline/core/about-1440-a11y.txt; /tmp/portfolio-feature-audit/baseline/core/about-390-full.png; /tmp/portfolio-feature-audit/baseline/core/about-768-full.png; /tmp/portfolio-feature-audit/baseline/core/about-1440-full-stable.png | P24: Not Started | Q24: Pass | R24: Pass — About showed the veteran/founder/full-stack narrative, current mission, product-to-maintenance delivery approach, semantic h1, and responsive portrait at 390/768/1440. Evidence: /tmp/portfolio-feature-audit/postfix/core/390/about-diagnostics.json; /tmp/portfolio-feature-audit/postfix/core/390/about-full.png; /tmp/portfolio-feature-audit/postfix/core/768/about-full.png; /tmp/portfolio-feature-audit/postfix/core/1440/about-full.png | T24: Unassigned | U24: 46257 | V24: 46257.605
A25: PF-ABOUT-002 | B25: Code Inventory | C25: /about studio link | D25: Visitor | E25: As a visitor, I want to open Steve’s studio. | F25: About narrative visible. | G25: Activate Defendre Solutions. | H25: Open studio site in protected new tab. | I25: Underlined focus-ring link. | J25: src/app/(site)/about/page.tsx:116-128 | K25: src/app/(site)/about/page.test.tsx:12-21 | L25: Active | M25: Pass | N25: Pass — Narrative studio link has secure blank-target behavior and opened the intended site; it appears in the keyboard tab order. Existing A11Y-EXT-001 disclosure gap remains. Evidence: /tmp/portfolio-feature-audit/baseline/core/about-390-dom.json; /tmp/portfolio-feature-audit/baseline/core/about-narrative-studio-tabs.txt; /tmp/portfolio-feature-audit/baseline/core/about-1440-a11y.txt | O25: A11Y-EXT-001 | P25: Fixed | Q25: Pass | R25: Pass — The narrative link now discloses the new tab in its accessible name, retains protected rel, and opened the correct studio destination. Evidence: /tmp/portfolio-feature-audit/postfix/core/390/about-diagnostics.json; /tmp/portfolio-feature-audit/postfix/core/external/about-studio-tabs.txt | T25: Unassigned | U25: 46257 | V25: 46257.605
A26: PF-ABOUT-003 | B26: Code Inventory | C26: /about proof points | D26: Visitor | E26: As a visitor, I want concise evidence of delivery range and stack. | F26: About route loads. | G26: Read proof points. | H26: Show studio, delivery range, and core stack values. | I26: Semantic definition list; responsive 1/3-column behavior. | J26: src/app/(site)/about/page.tsx:45-58,138-152 | K26: src/app/(site)/about/page.test.tsx:34-41 | L26: Active | M26: Pass | N26: Pass — All three term/definition pairs are present; captures show stacked mobile data and three-column tablet/desktop data. Evidence: /tmp/portfolio-feature-audit/baseline/core/about-1440-a11y.txt; /tmp/portfolio-feature-audit/baseline/core/about-390-full.png; /tmp/portfolio-feature-audit/baseline/core/about-768-full.png | P26: Not Started | Q26: Pass | R26: Pass — All three expected definition pairs rendered with complete values and no overflow. Evidence: /tmp/portfolio-feature-audit/postfix/core/390/about-diagnostics.json; /tmp/portfolio-feature-audit/postfix/core/1440/about-full.png | T26: Unassigned | U26: 46257 | V26: 46257.605
A27: PF-ABOUT-004 | B27: Code Inventory | C27: /about mission path | D27: Visitor | E27: As a visitor, I want Steve’s working principles. | F27: About route loads. | G27: Read ordered phases. | H27: Present Mission clarity, Delivery discipline, Owner-level judgment as phases 01-03. | I27: Ordered list; icons decorative; labelled section; responsive two-column layout. | J27: src/app/(site)/about/page.tsx:24-43,157-194 | K27: src/app/(site)/about/page.test.tsx:34-41 | L27: Active | M27: Pass | N27: Pass — Accessibility snapshot lists Phase 01/02/03 in order with required headings/copy; captures show connected vertical mobile/tablet and split desktop composition. Evidence: /tmp/portfolio-feature-audit/baseline/core/about-1440-a11y.txt; /tmp/portfolio-feature-audit/baseline/core/about-390-full.png; /tmp/portfolio-feature-audit/baseline/core/about-1440-full-stable.png | O27: DESIGN-AI-001 | P27: Won't Fix | Q27: Pass | R27: Pass — The ordered timeline exposed all three numbered phases and their full descriptions across responsive captures. Evidence: /tmp/portfolio-feature-audit/postfix/core/390/about-diagnostics.json; /tmp/portfolio-feature-audit/postfix/core/768/about-full.png | T27: Unassigned | U27: 46257 | V27: 46257.605
A28: PF-ABOUT-005 | B28: Code Inventory | C28: /about capabilities | D28: Visitor | E28: As a visitor, I want skill and capability coverage. | F28: About route loads. | G28: Read capability cards. | H28: Present Interface, Systems, Delivery, Infrastructure descriptions and skill lists. | I28: Labelled section; semantic articles/lists; two columns at md. | J28: src/app/(site)/about/page.tsx:60-81,196-234 | K28: src/app/(site)/about/page.test.tsx:22-33 | L28: Active | M28: Pass | N28: Pass — Interface, Systems, Delivery, and Infrastructure appear as four articles with labelled skill lists; mobile stack and 768/1440 2x2 layouts are visible and non-overflowing. Evidence: /tmp/portfolio-feature-audit/baseline/core/about-1440-a11y.txt; /tmp/portfolio-feature-audit/baseline/core/about-390-full.png; /tmp/portfolio-feature-audit/baseline/core/about-768-full.png; /tmp/portfolio-feature-audit/baseline/core/about-1440-full-stable.png | O28: DESIGN-AI-001 | P28: Won't Fix | Q28: Pass | R28: Pass — Interface, Systems, Delivery, and Infrastructure rendered with complete skill lists and responsive stack/grid presentation. Evidence: /tmp/portfolio-feature-audit/postfix/core/390/about-diagnostics.json; /tmp/portfolio-feature-audit/postfix/core/390/about-a11y.txt; /tmp/portfolio-feature-audit/postfix/core/1440/about-full.png | T28: Unassigned | U28: 46257 | V28: 46257.605
A29: PF-ABOUT-006 | B29: Code Inventory | C29: /about metadata | D29: Search/social crawler | E29: As a crawler, I want route-specific metadata. | F29: About route requested. | G29: Parse metadata. | H29: Use About title/description, canonical /about, and matching Open Graph URL/content. | I29: No visual behavior; accessible discoverability. | J29: src/app/(site)/about/page.tsx:9-22 | K29: No direct metadata assertion | L29: Active | M29: Pass | N29: Pass — Source, local HTTP, and public production all use the About title/description; local canonical/OG resolve to localhost and public canonical/OG consistently resolve to the production /about URL. Evidence: /tmp/portfolio-feature-audit/baseline/reconciliation/about-metadata-comparison.json; /tmp/portfolio-feature-audit/baseline/reconciliation/about-local-headers.txt; /tmp/portfolio-feature-audit/baseline/reconciliation/about-public-headers.txt | O29: CAND-RUNTIME-METADATA-001 | P29: Won't Fix | Q29: Pass | R29: Pass — Runtime title and description matched the contract; canonical and OG URL both resolved to /about and OG title/description matched route metadata. Evidence: /tmp/portfolio-feature-audit/postfix/core/390/about-diagnostics.json | T29: Unassigned | U29: 46257 | V29: 46257.605
A30: PF-PROJ-001 | B30: Code Inventory | C30: /projects metadata | D30: Search/social crawler | E30: As a crawler, I want route-specific project metadata. | F30: Projects route requested. | G30: Parse metadata. | H30: Use Projects title/description, canonical /projects, and matching Open Graph URL/content. | I30: No visual behavior. | J30: src/app/(site)/projects/page.tsx:5-16 | K30: src/app/(site)/projects/page.test.tsx:16-29 (catalog/category props; metadata not direct) | L30: Active | M30: Pass | N30: Pass — Title and descriptions matched; canonical and Open Graph URL both ended in /projects locally and used the correct production origin publicly. Evidence: /tmp/portfolio-feature-audit/baseline/projects/metadata-evidence.md; /tmp/portfolio-feature-audit/baseline/projects/1440/projects-all-full.png | O30: CAND-RUNTIME-METADATA-001 | P30: Won't Fix | Q30: Pass | R30: Pass — Title was Projects | Steve Defendre; description was route-specific; canonical and Open Graph URL matched each other and ended in /projects. Evidence: /tmp/portfolio-feature-audit/postfix/projects/1440/dom-audit.json; /tmp/portfolio-feature-audit/postfix/projects/1440/projects-all-full.png | T30: Unassigned | U30: 46257 | V30: 46257.605
A31: PF-PROJ-002 | B31: Code Inventory | C31: /projects overview | D31: Visitor | E31: As a visitor, I want the size and context of the archive. | F31: Projects route loads with catalog. | G31: Read header/current-view card. | H31: Show project overview, visible count, and “full archive” or active-category explanation. | I31: Semantic labelled section and h1; two-column header at lg. | J31: src/components/ProjectExplorer.tsx:34-98 | K31: src/components/__tests__/ProjectExplorer.test.tsx:68-78; e2e/projects.spec.ts:4-10 | L31: Active | M31: Pass | N31: Pass — Projects h1 and overview rendered; visible count was 7 initially and changed to 1 or 3 with matching context by filter. Evidence: /tmp/portfolio-feature-audit/baseline/projects/interaction-evidence.md; /tmp/portfolio-feature-audit/baseline/projects/1440/projects-all-full.png | P31: Not Started | Q31: Pass | R31: Pass — Projects h1 and overview rendered; initial count was 7 and context/count updated for every filter at all three widths. Evidence: /tmp/portfolio-feature-audit/postfix/projects/interaction-evidence.md; /tmp/portfolio-feature-audit/postfix/projects/390/projects-all-full.png; /tmp/portfolio-feature-audit/postfix/projects/768/projects-all-full.png; /tmp/portfolio-feature-audit/postfix/projects/1440/projects-all-full.png | T31: Unassigned | U31: 46257 | V31: 46257.605
A32: PF-PROJ-003 | B32: Code Inventory | C32: /projects category filters | D32: Visitor | E32: As a visitor, I want to filter by All, Studio, Client, or Product. | F32: Catalog/categories loaded. | G32: Activate a category chip. | H32: Exclusively set active filter and render only matching projects. | I32: Buttons are >=44px, grouped with role=group; aria-pressed exposes state. | J32: src/components/ProjectExplorer.tsx:100-145; src/data/projects.ts:1-4 | K32: src/components/__tests__/ProjectExplorer.test.tsx:68-92,114-136; e2e/projects.spec.ts:8-15 | L32: Active | M32: Pass | N32: Pass — Pointer, Enter, and Space activations produced 7/1/3/3 articles; exactly one aria-pressed state was true; every button measured 44px; URL stayed /projects. Evidence: /tmp/portfolio-feature-audit/baseline/projects/interaction-evidence.md; /tmp/portfolio-feature-audit/baseline/projects/interactions/filter-client-full.png | P32: Not Started | Q32: Pass | R32: Pass — All/Studio/Client/Product produced 7/1/3/3 cards at 390, exact 768, and 1440; one pressed state remained exclusive; buttons measured 44px; pointer, Enter, and Space activation passed; URL stayed /projects. Evidence: /tmp/portfolio-feature-audit/postfix/projects/interaction-evidence.md; /tmp/portfolio-feature-audit/postfix/projects/interactions/product-filter-full.png | T32: Unassigned | U32: 46257 | V32: 46257.605
A33: PF-PROJ-004 | B33: Code Inventory | C33: /projects live count | D33: Visitor/assistive tech | E33: As a visitor, I want filtering results announced. | F33: Filter state changes. | G33: Activate filter. | H33: Update singular/plural count (“Showing N … project(s)”). | I33: aria-live="polite"; visible count card also updates. | J33: src/components/ProjectExplorer.tsx:40-53,82-95,101-111 | K33: src/components/__tests__/ProjectExplorer.test.tsx:69-92; e2e/projects.spec.ts:8-15 | L33: Active | M33: Pass | N33: Pass — Announcements changed among Showing 7 of 7 projects, Showing 1 Studio project, Showing 3 Client projects, and Showing 3 Product projects; the visible count/context card updated in lockstep. Evidence: /tmp/portfolio-feature-audit/baseline/projects/interaction-evidence.md | P33: Not Started | Q33: Pass | R33: Pass — Announcements were Showing 7 of 7 projects, Showing 1 Studio project, Showing 3 Client projects, and Showing 3 Product projects at every required width, with matching visible counts. Evidence: /tmp/portfolio-feature-audit/postfix/projects/interaction-evidence.md; /tmp/portfolio-feature-audit/postfix/projects/390/dom-audit.json; /tmp/portfolio-feature-audit/postfix/projects/768/dom-audit.json | T33: Unassigned | U33: 46257 | V33: 46257.605
A34: PF-PROJ-005 | B34: Code Inventory | C34: /projects project cards | D34: Visitor | E34: As a visitor, I want role, outcome, description, tags, and status for every project. | F34: Visible catalog record exists. | G34: Read a card. | H34: Show preview, deployment/prototype label, title, description, Role, Outcome, tags, and CTA when URL is safe. | I34: Semantic content; responsive clamps and sizes; live/prototype color dot is supplemented by text. | J34: src/components/ProjectCard.tsx:50-200 | K34: src/components/__tests__/ProjectCard.test.tsx:5-176 | L34: Active | M34: Pass | N34: Pass — All seven cards exposed the complete expected content. Six showed Live/Live deployment and Traces showed Prototype. CTAs matched the catalog. Evidence: /tmp/portfolio-feature-audit/baseline/projects/1440/projects-all-full.png; /tmp/portfolio-feature-audit/baseline/projects/snapshot-1440.txt | O34: A11Y-IMG-001; DESIGN-AI-001 | P34: Fixed | Q34: Pass | R34: Pass — All seven cards exposed complete expected content. Six were Live/Live deployment; Traces was Prototype. Project-specific CTAs and catalog content matched. Evidence: /tmp/portfolio-feature-audit/postfix/projects/catalog-audit.json; /tmp/portfolio-feature-audit/postfix/projects/1440/projects-all-full.png | T34: Unassigned | U34: 46257 | V34: 46257.605
A35: PF-PROJ-006 | B35: Code Inventory | C35: /projects project images/fallback | D35: Visitor/assistive tech | E35: As a visitor, I want recognizable previews with graceful fallback. | F35: Record may have image or only initials/gradient. | G35: Load card. | H35: Use responsive optimized image with contextual alt; otherwise render decorative gradient/initials fallback. | I35: Images use async decode and lazy/eager policy; fallback is aria-hidden. | J35: src/components/ProjectCard.tsx:28-48,67-75,84-123; src/components/ResponsiveImage.tsx:20-43 | K35: src/components/__tests__/ProjectCard.test.tsx:79-93,118-159 | L35: Active | M35: Fail | N35: Fail — All seven images loaded responsively with nonzero natural width, but Traces was visibly Prototype while its alt said Traces live project preview. No catalog record lacked an image, so the fallback path was not runtime-reachable. Evidence: /tmp/portfolio-feature-audit/baseline/projects/console-network.md; /tmp/portfolio-feature-audit/baseline/projects/1440/projects-all-full.png | O35: PERF-IMG-001; A11Y-IMG-001 | P35: Fixed | Q35: Pass | R35: Pass — All seven previews returned HTTP 200, rendered responsively with nonzero natural dimensions during full coverage, used concise accurate alt, async decoding, lazy/auto loading, and responsive sizes. Traces no longer claims a live state. No catalog item lacks an image, so fallback remained runtime-unreachable. Evidence: /tmp/portfolio-feature-audit/postfix/projects/catalog-audit.json; /tmp/portfolio-feature-audit/postfix/projects/candidate-evidence.md; /tmp/portfolio-feature-audit/postfix/projects/390/dom-audit.json | T35: Unassigned | U35: 46257 | V35: 46257.605
A36: PF-PROJ-007 | B36: Code Inventory | C36: /projects responsive detail density | D36: Mobile/desktop visitor | E36: As a visitor, I want cards readable without overload. | F36: Compact card rendered. | G36: View at different widths. | H36: Compact description/outcome clamps; tags after third hide until lg; featured card expands at lg. | I36: Responsive visual density without removing core title/CTA/status. | J36: src/components/ProjectCard.tsx:65-87,142-191 | K36: src/components/__tests__/ProjectCard.test.tsx:94-117 | L36: Active | M36: Pass | N36: Pass — Fourth tags were hidden at 390 and 768 and visible at 1440; core title/status/CTA remained present; no overflow occurred. Evidence: /tmp/portfolio-feature-audit/baseline/projects/390/projects-all-full.png; /tmp/portfolio-feature-audit/baseline/projects/768/projects-all-full.png; /tmp/portfolio-feature-audit/baseline/projects/1440/projects-all-full.png | P36: Not Started | Q36: Pass | R36: Pass — Cards were 358px at 390, 720px at exact 768, and two ~652px columns at 1440 with no overflow. Fourth tags were hidden at 390/768 and visible at 1440; core content remained. Evidence: /tmp/portfolio-feature-audit/postfix/projects/390/dom-audit.json; /tmp/portfolio-feature-audit/postfix/projects/768/dom-audit.json; /tmp/portfolio-feature-audit/postfix/projects/interaction-evidence.md | T36: Unassigned | U36: 46257 | V36: 46257.605
A37: PF-PROJ-008 | B37: Code Inventory | C37: /projects external project link | D37: Visitor/security system | E37: As a visitor, I want to open a project safely. | F37: Project has safe URL. | G37: Activate the card. | H37: Entire card opens configured URL in new tab with noopener noreferrer; aria-label includes CTA, title, and “opens in new tab.” | I37: One large focusable target; unsafe/missing URL renders non-link card. | J37: src/components/ProjectCard.tsx:67,194-218 | K37: src/components/__tests__/ProjectCard.test.tsx:45-76,118-159; src/components/__tests__/ProjectExplorer.test.tsx:138-162 | L37: Active | M37: Pass | N37: Pass — All seven full-card links had target=_blank, noopener noreferrer, and project/CTA/new-tab accessible names; browser activation opened all configured external destinations while retaining Projects. Evidence: /tmp/portfolio-feature-audit/baseline/projects/interaction-evidence.md; /tmp/portfolio-feature-audit/baseline/projects/snapshot-1440.txt | O37: A11Y-EXT-001 | P37: Fixed | Q37: Pass | R37: Pass — All seven cards had target=_blank, noopener noreferrer, and CTA/title/new-tab accessible names. New-tab activation retained Projects and opened every configured external destination. Evidence: /tmp/portfolio-feature-audit/postfix/projects/catalog-audit.json; /tmp/portfolio-feature-audit/postfix/projects/interaction-evidence.md | T37: Unassigned | U37: 46257 | V37: 46257.605
A38: PF-PROJ-009 | B38: Code Inventory | C38: /projects inline case study | D38: Visitor | E38: As a visitor, I want deeper context without leaving the archive. | F38: Project article visible. | G38: Expand its Case study summary. | H38: Reveal Challenge, Approach, and Impact; chevron rotates on open. | I38: Native details/summary; 44px summary; screen-only title disambiguates project; three columns at sm. | J38: src/components/ProjectExplorer.tsx:175-218 | K38: src/components/__tests__/ProjectExplorer.test.tsx:138-162; e2e/projects.spec.ts:16-23 | L38: Active | M38: Pass | N38: Pass — All seven opened by pointer with project-specific three-part content; each also opened with Enter and closed with Space; summaries measured 44px and stayed focused. Evidence: /tmp/portfolio-feature-audit/baseline/projects/interaction-evidence.md; /tmp/portfolio-feature-audit/baseline/projects/interactions/all-case-studies-pointer-open.png; /tmp/portfolio-feature-audit/baseline/projects/768/case-study-open.png | O38: DESIGN-AI-001 | P38: Won't Fix | Q38: Pass | R38: Pass — At 390, exact 768, and 1440 all seven opened by pointer, revealed all three nonempty project-specific parts, opened with Enter, closed with Space, measured 44px, and retained focus. Evidence: /tmp/portfolio-feature-audit/postfix/projects/interaction-evidence.md; /tmp/portfolio-feature-audit/postfix/projects/interactions/all-case-studies-pointer-open.png; /tmp/portfolio-feature-audit/postfix/projects/768/case-studies-open.png | T38: Unassigned | U38: 46257 | V38: 46257.605
A39: PF-PROJ-010 | B39: Code Inventory | C39: /projects empty state/reset | D39: Visitor | E39: As a visitor, I want recovery when a category has no matches. | F39: Active filter has zero projects. | G39: Read empty state or activate “Show all projects.” | H39: Show no-match explanation and reset to All. | I39: Semantic heading; 44px reset button; count announcement remains live. | J39: src/components/ProjectExplorer.tsx:222-241 | K39: src/components/__tests__/ProjectExplorer.test.tsx:94-112 | L39: Active | M39: Blocked | N39: Blocked — All three fixed categories contain at least one project and there is no user-entered category or URL filter, so the zero-result precondition and reset control are unreachable in the shipped browser UI without changing/injecting app data. Evidence: /tmp/portfolio-feature-audit/baseline/projects/interaction-evidence.md | P39: Deferred | Q39: Blocked | R39: Blocked — Studio has 1 project and Client/Product each have 3. There is no free-form or URL filter, so no shipped interaction produces zero results without changing or injecting app data. Evidence: /tmp/portfolio-feature-audit/postfix/projects/interaction-evidence.md | T39: Unassigned | U39: 46257 | V39: 46257.605
